Workbook
Name Resource_Billability: '[1]Control Reference'!$E$13:$E$15
Name Role_Level: '[2]Control Reference'!$G$8:$G$48
Name Type: '[3]Maintenance Work Order'!#REF!

Sheet MainPage
B1: PMWB-Project Name_MonthYear
B4: Template ID | C4: ENPMT18
B6: Template Name | C6: PMWB-Project Name_MonthYear
B8: Template Version | C8: 1.3
B10: Author | C10: QMG
C11: Changes made -
C12: 1. Change in InterraIT logo 2. Restructuring of the document 3. Risk updated as per ISMS
B13: Template Release Date | C13: 45890

Sheet Project Info
A1: Project Information
A2: Project Name
A3: Project Code/PIN | C3: Status
A4: Project Category | C4: Project Type
A6: Customer Name & Address | B6: Mazda North American Operation(MNAO)
A7: Customer's Line of Business | B7: Automotive
A8: Primary Contact Person | B8: Paula Neil(PNeil@mazdausa.com/1-949-727-6305
A10: Project Start Date in SOW | C10: Project Completion Date in SOW
A11: Plan Start Date | C11: Plan Completion Date
A12: Revised Plan Start Date | C12: Revised Plan Completion Date
A13: Actual Start Date | C13: Actual Completion Date
A15: Estimated Effort(Hrs) | C15: Approved Effort(Hrs) | D15: =B15*90% -> 0
A16: Actual Effort Consumed(Hrs) | B16: =PSR!R28+PSR!I28 -> 0 | C16: Remaining Effort | D16: =D15-B16 -> 0
A18: SOW Onsite FTEs | C18: SOW Offshore FTEs
A19: Actual Onsite FTEs | B19: =PSR!R28/8 -> 0 | C19: Actual Offshore FTEs | D19: =PSR!I28/8 -> 0
A23: Date | B23: Version No. | C23: Changes | D23: Updated by

Sheet Project information1
A1: Project Name | C1: Customer name | E1: Links to Sheets | H1: =IF(ISERROR(SMALL('Control panel'!D$3:D$23,ROW())),"",INDIRECT("'Control panel'!B" & SMALL('Control panel'!D$3:D$23,ROW()),2)) -> Hours | I1: Technology | J1: Programming Language | K1: Platform | L1: BU : SAP CS | M1: DE Development | N1: Bangalore - 23 Airport Road
A2: SAP Project Code | C2: Plan start date | D2: =#REF! -> #REF! | E2: Control Panel | H2: =IF(ISERROR(SMALL('Control panel'!D$3:D$23,ROW())),"",INDIRECT("'Control panel'!B" & SMALL('Control panel'!D$3:D$23,ROW()),2)) | I2: Application | J2: 1032/AF | K2: A7/ZSP | L2: BU : SAP Hewitt Associates | M2: MM Maintenance - Migration | N2: Bangalore - 33A Ulsoor Road
A3: Business Unit (SAP) | C3: Plan completion date | D3: =#REF! -> #REF! | E3: Planning | H3: =IF(ISERROR(SMALL('Control panel'!D$3:D$23,ROW())),"",INDIRECT("'Control panel'!B" & SMALL('Control panel'!D$3:D$23,ROW()),2)) | I3: AS/400 | J3: 1st Generation default | K3: AS/400 | L3: BU : SAP AMD | M3: MP Maintenance - Porting | N3: Bangalore - 5 100 Ft Road
A4: Business Model | C4: Revised start date | D4: =#REF! -> #REF! | E4: Metrics plan | H4: =IF(ISERROR(SMALL('Control panel'!D$3:D$23,ROW())),"",INDIRECT("'Control panel'!B" & SMALL('Control panel'!D$3:D$23,ROW()),2)) | I4: Client/Server | J4: 2nd Generation default | K4: Embedded | L4: BU : SAP Dom Projects | M4: MS Maintenance - Small SDLC | N4: Bangalore - 8, 9 GB Palya
A5: Project Type | C5: Revised completion date | D5: =#REF! -> #REF! | E5: Staffing | H5: =IF(ISERROR(SMALL('Control panel'!D$3:D$23,ROW())),"",INDIRECT("'Control panel'!B" & SMALL('Control panel'!D$3:D$23,ROW()),2)) | I5: Embedded | J5: 3rd Generation default | K5: JTAG | L5: BU : SAP NCR Projects | M5: PI Package Implementation | N5: Chennai - 158 Arcot Road
A6: Project Location | C6: Actual start date | D6: =#REF! -> #REF! | E6: Training | H6: =IF(ISERROR(SMALL('Control panel'!D$3:D$23,ROW())),"",INDIRECT("'Control panel'!B" & SMALL('Control panel'!D$3:D$23,ROW()),2)) | I6: Enterprise Data Warehousing | J6: 4th Generation default | K6: Linux | L6: BU : SAP B'lore | M6: PS Product Sales | N6: Chennai - 184 NSK Road
A7: Project Manager | C7: Actual completion date | E7: Subprocess goal tracking | H7: =IF(ISERROR(SMALL('Control panel'!D$3:D$23,ROW())),"",INDIRECT("'Control panel'!B" & SMALL('Control panel'!D$3:D$23,ROW()),2)) | I7: Imaging | J7: 5th Generation default | K7: Mobile | L7: BU : SAP Kolkata | M7: SC Scoping | N7: Chennai - 30 C-in-C Road
A8: Senior Manager | C8: Initial estimated effort | D8: =#REF! -> #REF! | E8: Risk Management | H8: =IF(ISERROR(SMALL('Control panel'!D$3:D$23,ROW())),"",INDIRECT("'Control panel'!B" & SMALL('Control panel'!D$3:D$23,ROW()),2)) | I8: Mainframe | J8: AAS Macro | K8: Nucleus | L8: BU : SAP Chennai - Rockwell | M8: TE Testing | N8: Chennai - 30 Ethiraj Salai
A9: Engineering Staff | C9: Revised effort | D9: =#REF! -> #REF! | E9: Recruitment Plan | H9: =IF(ISERROR(SMALL('Control panel'!D$3:D$23,ROW())),"",INDIRECT("'Control panel'!B" & SMALL('Control panel'!D$3:D$23,ROW()),2)) | I9: Microsoft Technologies | J9: ABAP/4 | K9: Open VMS | L9: BU : SAP Chennai - Others | M9: OT Other | N9: Chennai - 34-35 Haddows Road
A10: Initial estimate size | B10: =#REF! -> #REF! | C10: Actual effort | D10: =#REF! -> #REF! | E10: IT Services Plan | H10: =IF(ISERROR(SMALL('Control panel'!D$3:D$23,ROW())),"",INDIRECT("'Control panel'!B" & SMALL('Control panel'!D$3:D$23,ROW()),2)) | I10: Others | J10: ACCEL | K10: Others | L10: BU : SAP SMH | N10: Chennai - 43-44 Montieth Road
A11: Revised size | B11: =#REF! -> #REF! | C11: Effort unit | E11: Size, Schedule and Effort | H11: =IF(ISERROR(SMALL('Control panel'!D$3:D$23,ROW())),"",INDIRECT("'Control panel'!B" & SMALL('Control panel'!D$3:D$23,ROW()),2)) | J11: Access | K11: UNIX | L11: BU : SAP ANZ | N11: Chennai - 50-53 Greams Road
A12: Actual Size | B12: =#REF! -> #REF! | C12: Estimates revised on | E12: Verification data | H12: =IF(ISERROR(SMALL('Control panel'!D$3:D$23,ROW())),"",INDIRECT("'Control panel'!B" & SMALL('Control panel'!D$3:D$23,ROW()),2)) | J12: ACTOR | K12: Windows | L12: BU : SAP US | N12: Chennai - 51 JN Road
A13: Size Unit | C13: Primary Dev. Language | E13: Verification Summary | H13: =IF(ISERROR(SMALL('Control panel'!D$3:D$23,ROW())),"",INDIRECT("'Control panel'!B" & SMALL('Control panel'!D$3:D$23,ROW()),2)) | J13: Acumen | L13: BU : SAP Europe | N13: Chennai - 35 South Phase (Guindy)
A14: Platform | C14: Project Technology | E14: Quality of work | H14: =IF(ISERROR(SMALL('Control panel'!D$3:D$23,ROW())),"",INDIRECT("'Control panel'!B" & SMALL('Control panel'!D$3:D$23,ROW()),2)) | J14: Ada 83 | L14: BU : SAP COE | N14: Chennai - 602 Tidel Park
A15: Project Status | D15: Guidelines | E15: Phasewise EV-SV | H15: =IF(ISERROR(SMALL('Control panel'!D$3:D$23,ROW())),"",INDIRECT("'Control panel'!B" & SMALL('Control panel'!D$3:D$23,ROW()),2)) | J15: Ada 95 | L15: BU : OU Teradyne | N15: Chennai - 78 South Phase Road (Ambattur)
D16: Accomplishments and Incidents | E16: Charts | H16: =IF(ISERROR(SMALL('Control panel'!D$3:D$23,ROW())),"",INDIRECT("'Control panel'!B" & SMALL('Control panel'!D$3:D$23,ROW()),2)) | J16: ADR/DL | L16: BU : OU Hewitt Associates | N16: Chennai - 84 Greams Road
D17: CR Information | E17: Corrective action | H17: =IF(ISERROR(SMALL('Control panel'!D$3:D$23,ROW())),"",INDIRECT("'Control panel'!B" & SMALL('Control panel'!D$3:D$23,ROW()),2)) | J17: ADR/IDEAL/PDL | L17: BU : OU BFSI | N17: Chennai - 64-66 South Phase Road (Ambattur)
A18: Date | B18: Rev | C18: Changes | D18: Updated by | E18: Tracking effort in hours | J18: ADS/Batch | L18: BU : OU MFG | N18: Chennai - D12 & 12B Industrial Estate (Ambattur)
J19: ADS/Online | L19: BU : OU HI Tech | N19: Chennai - J-16 Anna Nagar
J20: AI shell default | L20: BU : OU MPE | N20: Chennai - NM Road
J21: AI SHELLS | L21: BU : OU Telecon | N21: Chennai - PH Road
J22: ALGOL 68 | L22: BU : OU Retail & Others | N22: Chennai - PM Towers
J23: ALGOL W | L23: BU : OU Life Sciences | N23: Gurgaon (244) - Phase 1
J24: AMBUSH | L24: BU : OU COE/Skill Pool | N24: Gurgaon (3) - Phase 1
J25: AML | L25: BU : MBS | N25: Kolkata - Sector V, Salt Lake
J26: AMPPL II | L26: BU : Placement projects | N26: Noida (A/104) - Sector 58
J27: ANSI BASIC | L27: BU : EAI - (India) | N27: Noida (A-1) - Sector 16
J28: ANSI COBOL 74 | L28: BU : EAI - (Alayance) | N28: Noida (A-10/11) - Sector 3
J29: ANSI COBOL 85 | L29: CBU : PEARSON | N29: Noida (A-11) - Sector 16
J30: ANSI SQL | L30: CBU: LN/ NE | N30: Noida (A-5) - Sector 24
... J35: APPLESOFT BASIC | L35: IS - MPE - ECMP Documentum | N35: Other
J36: Application Builder | L36: IS - MPE - ECMP Others
J37: Application Manager | L37: VERTICAL: ACS-HTM-NOIDA
J38: APS | L38: OBU: TECH SUPORT BGL
J39: APT | L39: OBU: TECH SUPPORT CHENNAI
J40: APTools | L40: OBU: ACS HYD
J41: ARC | L41: IS - HTM - ECMP Documentum
J42: Ariel | L42: IS - HTM - ECMP Others
J43: ARITY | L43: VERTICAL : PHARMA CHENNAI
J44: Arity PROLOG | L44: VERTICAL : HEALTHCARE CHENNAI
...

Sheet Charts
A1: Schedule
A2: Effort
A3: WDD | V3: =COUNT(#REF!) -> 0
A4: Productivity | V4: ='Size, Schedule and Effort'!Z1-1 -> 2
I5: =COUNTA('Size, Schedule and Effort'!A:A)-1 -> 7 | J5: {=MAX(IF('Quality of Work'!E19:E120<>"",ROW('Quality of Work'!E19:E120),0))} -> 23 | K5: =COUNT(#REF!) -> 0 | L5: =COUNT(#REF!) -> 0 | M5: =COUNT('Verification Summary'!Q9:Q24) -> 6
W92: =COUNTA(#REF!)-COUNTBLANK(#REF!) -> #REF!

Sheet PSR
A1: Project Status Review
A2: Planned Productivity ( Till Current period) | B2: =IF(H28=0,"",G47/H28) | C2: Resource Level | D2: No# | E2: Resource Level | F2: No# | G2: Resource Level | H2: No# | I2: Project Start Dt. | K2: ='Project Info'!B12 -> 0
A3: Actual Productivity ( Till Current period) | B3: =IF(I28=0,"",G47/I28) | C3: L1 | D3: =COUNTIF(Resources!$F$18:$F$86,C3) -> 0 | E3: L5 | F3: =COUNTIF(Resources!$F$18:$F$86,E3) -> 0 | G3: L9 | H3: =COUNTIF(Resources!$F$18:$F$86,G3) -> 0 | I3: Project End Dt. | K3: ='Project Info'!D12 -> 0
A4: Current Team Size | B4: =SUMIF(Resources!$P$18:$P$86,"Available ",Resources!$Q$18:$Q$86) -> 0 | C4: L2 | D4: =COUNTIF(Resources!$F$18:$F$86,C4) -> 0 | E4: L6 | F4: =COUNTIF(Resources!$F$18:$F$86,E4) -> 0 | G4: L10 | H4: =COUNTIF(Resources!$F$18:$F$86,G4) -> 0 | I4: Current Date
A5: No. of Persons Resigned | B5: =SUMIF(Resources!$P$18:$P$86,"Resigned",Resources!$R$18:$R$86) -> 0 | C5: L3 | D5: =COUNTIF(Resources!$F$18:$F$86,C5) -> 0 | E5: L7 | F5: =COUNTIF(Resources!$F$18:$F$86,E5) -> 0 | H5: =COUNTIF(Resources!$F$18:$F$86,G5) -> 0
A6: No. of Persons currently Not Available in project | B6: =SUMIF(Resources!$P$18:$P$86,"Not Available",Resources!$S$18:$S$86) -> 0 | C6: L4 | D6: =COUNTIF(Resources!$F$18:$F$86,C6) -> 0 | E6: L8 | F6: =COUNTIF(Resources!$F$18:$F$86,E6) -> 0 | H6: =COUNTIF(Resources!$F$18:$F$86,G6) -> 0
B8: Note - Please put the efforts belonging to the 'current cumulative' blocks to 'Upto last period' block
A13: 1. PROJECT EFFORT
A15: Effort as per Type (Man-hours) | B15: Offshore | K15: Onsite
B16: Upto Last Period | E16: Current Period | H16: Current Cumulative | K16: Upto Last Period | N16: Current Period | Q16: Current Cumulative
B17: Planned | C17: Actual | D17: Deviation (%) | E17: Planned | F17: Actual | G17: Deviation (%) | H17: Planned | I17: Actual | J17: Deviation (%) | K17: Planned | L17: Actual | M17: Deviation (%) | N17: Planned | O17: Actual | P17: Deviation (%) | Q17: Planned | R17: Actual | S17: Deviation (%)
A18: Project Team Effort (Man-Hrs) | D18: =IF(B18=0,0,((B18-C18)/B18)*100) -> 0 | E18: =Resources!G4 -> 0 | F18: =Resources!I4 -> 0 | G18: =IF(E18=0,0,((E18-F18)/E18)*100) -> 0 | H18: =E18+B18 -> 0 | I18: =C18+F18 -> 0 | J18: =IF(H18=0,0,((H18-I18)/H18)*100) -> 0 | K18: 0 | L18: 0 | M18: =IF(K18=0,0,((K18-L18)/K18)*100) -> 0 | N18: =Resources!L4 -> 0 | O18: =Resources!N4 -> 0 | P18: =IF(N18=0,0,((N18-O18)/N18)*100) -> 0 | Q18: =N18+K18 -> 0 | R18: =L18+O18 -> 0 | S18: =IF(Q18=0,0,((Q18-R18)/Q18)*100) -> 0
A19: Testing Team Effort (Man-Hrs) | D19: =IF(B19=0,0,((B19-C19)/B19)*100) -> 0 | E19: =Resources!G5 -> 0 | F19: =Resources!I5 -> 0 | G19: =IF(E19=0,0,((E19-F19)/E19)*100) -> 0 | H19: =E19+B19 -> 0 | I19: =C19+F19 -> 0 | J19: =IF(H19=0,0,((H19-I19)/H19)*100) -> 0 | K19: 0 | L19: 0 | M19: =IF(K19=0,0,((K19-L19)/K19)*100) -> 0 | N19: =Resources!L5 -> 0 | O19: =Resources!N5 -> 0 | P19: =IF(N19=0,0,((N19-O19)/N19)*100) -> 0 | Q19: =N19+K19 -> 0 | R19: =L19+O19 -> 0 | S19: =IF(Q19=0,0,((Q19-R19)/Q19)*100) -> 0
A20: Graphics Efforts (Man-Hrs) | D20: =IF(B20=0,0,((B20-C20)/B20)*100) -> 0 | E20: =Resources!G6 -> 0 | F20: =Resources!I6 -> 0 | G20: =IF(E20=0,0,((E20-F20)/E20)*100) -> 0 | H20: =E20+B20 -> 0 | I20: =C20+F20 -> 0 | J20: =IF(H20=0,0,((H20-I20)/H20)*100) -> 0 | K20: 0 | L20: 0 | M20: =IF(K20=0,0,((K20-L20)/K20)*100) -> 0 | N20: =Resources!L6 -> 0 | O20: =Resources!N6 -> 0 | P20: =IF(N20=0,0,((N20-O20)/N20)*100) -> 0 | Q20: =N20+K20 -> 0 | R20: =L20+O20 -> 0 | S20: =IF(Q20=0,0,((Q20-R20)/Q20)*100) -> 0
A21: Tech. Writer Efforts (Man-Hrs) | D21: =IF(B21=0,0,((B21-C21)/B21)*100) -> 0 | E21: =Resources!G7 -> 0 | F21: =Resources!I7 -> 0 | G21: =IF(E21=0,0,((E21-F21)/E21)*100) -> 0 | H21: =E21+B21 -> 0 | I21: =C21+F21 -> 0 | J21: =IF(H21=0,0,((H21-I21)/H21)*100) -> 0 | K21: 0 | L21: 0 | M21: =IF(K21=0,0,((K21-L21)/K21)*100) -> 0 | N21: =Resources!L7 -> 0 | O21: =Resources!N7 -> 0 | P21: =IF(N21=0,0,((N21-O21)/N21)*100) -> 0 | Q21: =N21+K21 -> 0 | R21: =L21+O21 -> 0 | S21: =IF(Q21=0,0,((Q21-R21)/Q21)*100) -> 0
A22: QA Efforts (Man-Hrs) | D22: =IF(B22=0,0,((B22-C22)/B22)*100) -> 0 | E22: =Resources!G8 -> 0 | F22: =Resources!I8 -> 0 | G22: =IF(E22=0,0,((E22-F22)/E22)*100) -> 0 | H22: =E22+B22 -> 0 | I22: =C22+F22 -> 0 | J22: =IF(H22=0,0,((H22-I22)/H22)*100) -> 0 | K22: 0 | L22: 0 | M22: =IF(K22=0,0,((K22-L22)/K22)*100) -> 0 | N22: =Resources!L8 -> 0 | O22: =Resources!N8 -> 0 | P22: =IF(N22=0,0,((N22-O22)/N22)*100) -> 0 | Q22: =N22+K22 -> 0 | R22: =L22+O22 -> 0 | S22: =IF(Q22=0,0,((Q22-R22)/Q22)*100) -> 0
A23: Organizational Efforts (Man-Hrs) | D23: =IF(B23=0,0,((B23-C23)/B23)*100) -> 0 | E23: =Resources!G9 -> 0 | F23: =Resources!I9 -> 0 | G23: =IF(E23=0,0,((E23-F23)/E23)*100) -> 0 | H23: =E23+B23 -> 0 | I23: =C23+F23 -> 0 | J23: =IF(H23=0,0,((H23-I23)/H23)*100) -> 0 | K23: 0 | L23: 0 | M23: =IF(K23=0,0,((K23-L23)/K23)*100) -> 0 | N23: =Resources!L9 -> 0 | O23: =Resources!N9 -> 0 | P23: =IF(N23=0,0,((N23-O23)/N23)*100) -> 0 | Q23: =N23+K23 -> 0 | R23: =L23+O23 -> 0 | S23: =IF(Q23=0,0,((Q23-R23)/Q23)*100) -> 0
A24: PM Efforts (Man-Hrs) | D24: =IF(B24=0,0,((B24-C24)/B24)*100) -> 0 | E24: =Resources!G10 -> 0 | F24: =Resources!I10 -> 0 | G24: =IF(E24=0,0,((E24-F24)/E24)*100) -> 0 | H24: =E24+B24 -> 0 | I24: =C24+F24 -> 0 | J24: =IF(H24=0,0,((H24-I24)/H24)*100) -> 0 | K24: 0 | L24: 0 | M24: =IF(K24=0,0,((K24-L24)/K24)*100) -> 0 | N24: =Resources!L10 -> 0 | O24: =Resources!N10 -> 0 | P24: =IF(N24=0,0,((N24-O24)/N24)*100) -> 0 | Q24: =N24+K24 -> 0 | R24: =L24+O24 -> 0 | S24: =IF(Q24=0,0,((Q24-R24)/Q24)*100) -> 0
A25: Architecture (Man-Hrs) | D25: =IF(B25=0,0,((B25-C25)/B25)*100) -> 0 | E25: =Resources!G11 -> 0 | F25: =Resources!I11 -> 0 | G25: =IF(E25=0,0,((E25-F25)/E25)*100) -> 0 | H25: =E25+B25 -> 0 | I25: =C25+F25 -> 0 | J25: =IF(H25=0,0,((H25-I25)/H25)*100) -> 0 | K25: 0 | L25: 0 | M25: =IF(K25=0,0,((K25-L25)/K25)*100) -> 0 | N25: =Resources!L11 -> 0 | O25: =Resources!N11 -> 0 | P25: =IF(N25=0,0,((N25-O25)/N25)*100) -> 0 | Q25: =N25+K25 -> 0 | R25: =L25+O25 -> 0 | S25: =IF(Q25=0,0,((Q25-R25)/Q25)*100) -> 0
A26: Business Analyst Efforts (Man-Hrs) | D26: =IF(B26=0,0,((B26-C26)/B26)*100) -> 0 | E26: =Resources!G12 -> 0 | F26: =Resources!I12 -> 0 | G26: =IF(E26=0,0,((E26-F26)/E26)*100) -> 0 | H26: =E26+B26 -> 0 | I26: =C26+F26 -> 0 | J26: =IF(H26=0,0,((H26-I26)/H26)*100) -> 0 | K26: 0 | L26: 0 | M26: =IF(K26=0,0,((K26-L26)/K26)*100) -> 0 | N26: =Resources!L12 -> 0 | O26: =Resources!N12 -> 0 | P26: =IF(N26=0,0,((N26-O26)/N26)*100) -> 0 | Q26: =N26+K26 -> 0 | R26: =L26+O26 -> 0 | S26: =IF(Q26=0,0,((Q26-R26)/Q26)*100) -> 0
A27: PMO Efforts (Man-Hrs) | D27: =IF(B27=0,0,((B27-C27)/B27)*100) -> 0 | E27: =Resources!G13 -> 0 | F27: =Resources!I13 -> 0 | G27: =IF(E27=0,0,((E27-F27)/E27)*100) -> 0 | H27: =E27+B27 -> 0 | I27: =C27+F27 -> 0 | J27: =IF(H27=0,0,((H27-I27)/H27)*100) -> 0 | K27: 0 | L27: 0 | M27: =IF(K27=0,0,((K27-L27)/K27)*100) -> 0 | N27: =Resources!L13 -> 0 | O27: =Resources!N13 -> 0 | P27: =IF(N27=0,0,((N27-O27)/N27)*100) -> 0 | Q27: =N27+K27 -> 0 | R27: =L27+O27 -> 0 | S27: =IF(Q27=0,0,((Q27-R27)/Q27)*100) -> 0
A28: Total Project Efforts (Man-Hrs) | B28: =SUM(B18:B27) -> 0 | C28: =SUM(C18:C27) -> 0 | D28: =SUM(D18:D27) -> 0 | E28: =SUM(E18:E27) -> 0 | F28: =SUM(F18:F27) -> 0 | G28: =SUM(G18:G27) -> 0 | H28: =SUM(H18:H27) -> 0 | I28: =SUM(I18:I27) -> 0 | ... S28: =SUM(S18:S27) -> 0
A30: Effort as per Resource Level (Man-hours) | B30: Offshore | K30: Onsite
B31: Upto Last Period | E31: Current Period | H31: Current Cumulative | K31: Upto Last Period | N31: Current Period | Q31: Current Cumulative
B32: Planned | C32: Actual | D32: Deviation (%) | E32: Planned | F32: Actual | G32: Deviation (%) | H32: Planned | I32: Actual | J32: Deviation (%) | K32: Planned | L32: Actual | M32: Deviation (%) | N32: Planned | O32: Actual | P32: Deviation (%) | Q32: Planned | R32: Actual | S32: Deviation (%)
A33: L1 | D33: =IF(B33=0,0,((B33-C33)/B33)*100) -> 0 | E33: =Resources!Z4 -> 0 | F33: =Resources!AB4 -> 0 | G33: =IF(E33=0,0,((E33-F33)/E33)*100) -> 0 | H33: =E33+B33 -> 0 | I33: =C33+F33 -> 0 | J33: =IF(H33=0,0,((H33-I33)/H33)*100) -> 0 | K33: 0 | L33: 0 | M33: =IF(K33=0,0,((K33-L33)/K33)*100) -> 0 | N33: =Resources!AE4 -> 0 | O33: =Resources!AG4 -> 0 | P33: =IF(N33=0,0,((N33-O33)/N33)*100) -> 0 | Q33: =N33+K33 -> 0 | R33: =L33+O33 -> 0 | S33: =IF(Q33=0,0,((Q33-R33)/Q33)*100) -> 0
A34: L2 | D34: =IF(B34=0,0,((B34-C34)/B34)*100) -> 0 | E34: =Resources!Z5 -> 0 | F34: =Resources!AB5 -> 0 | G34: =IF(E34=0,0,((E34-F34)/E34)*100) -> 0 | H34: =E34+B34 -> 0 | I34: =C34+F34 -> 0 | J34: =IF(H34=0,0,((H34-I34)/H34)*100) -> 0 | K34: 0 | L34: 0 | M34: =IF(K34=0,0,((K34-L34)/K34)*100) -> 0 | N34: =Resources!AE5 -> 0 | O34: =Resources!AG5 -> 0 | P34: =IF(N34=0,0,((N34-O34)/N34)*100) -> 0 | Q34: =N34+K34 -> 0 | R34: =L34+O34 -> 0 | S34: =IF(Q34=0,0,((Q34-R34)/Q34)*100) -> 0
A35: L3 | D35: =IF(B35=0,0,((B35-C35)/B35)*100) -> 0 | E35: =Resources!Z6 -> 0 | F35: =Resources!AB6 -> 0 | G35: =IF(E35=0,0,((E35-F35)/E35)*100) -> 0 | H35: =E35+B35 -> 0 | I35: =C35+F35 -> 0 | J35: =IF(H35=0,0,((H35-I35)/H35)*100) -> 0 | K35: 0 | L35: 0 | M35: =IF(K35=0,0,((K35-L35)/K35)*100) -> 0 | N35: =Resources!AE6 -> 0 | O35: =Resources!AG6 -> 0 | P35: =IF(N35=0,0,((N35-O35)/N35)*100) -> 0 | Q35: =N35+K35 -> 0 | R35: =L35+O35 -> 0 | S35: =IF(Q35=0,0,((Q35-R35)/Q35)*100) -> 0
A36: L4 | D36: =IF(B36=0,0,((B36-C36)/B36)*100) -> 0 | E36: =Resources!Z7 -> 0 | F36: =Resources!AB7 -> 0 | G36: =IF(E36=0,0,((E36-F36)/E36)*100) -> 0 | H36: =E36+B36 -> 0 | I36: =C36+F36 -> 0 | J36: =IF(H36=0,0,((H36-I36)/H36)*100) -> 0 | K36: 0 | L36: 0 | M36: =IF(K36=0,0,((K36-L36)/K36)*100) -> 0 | N36: =Resources!AE7 -> 0 | O36: =Resources!AG7 -> 0 | P36: =IF(N36=0,0,((N36-O36)/N36)*100) -> 0 | Q36: =N36+K36 -> 0 | R36: =L36+O36 -> 0 | S36: =IF(Q36=0,0,((Q36-R36)/Q36)*100) -> 0
A37: L5 | D37: =IF(B37=0,0,((B37-C37)/B37)*100) -> 0 | E37: =Resources!Z8 -> 0 | F37: =Resources!AB8 -> 0 | G37: =IF(E37=0,0,((E37-F37)/E37)*100) -> 0 | H37: =E37+B37 -> 0 | I37: =C37+F37 -> 0 | J37: =IF(H37=0,0,((H37-I37)/H37)*100) -> 0 | K37: 0 | L37: 0 | M37: =IF(K37=0,0,((K37-L37)/K37)*100) -> 0 | N37: =Resources!AE8 -> 0 | O37: =Resources!AG8 -> 0 | P37: =IF(N37=0,0,((N37-O37)/N37)*100) -> 0 | Q37: =N37+K37 -> 0 | R37: =L37+O37 -> 0 | S37: =IF(Q37=0,0,((Q37-R37)/Q37)*100) -> 0
A38: L6 | D38: =IF(B38=0,0,((B38-C38)/B38)*100) -> 0 | E38: =Resources!Z9 -> 0 | F38: =Resources!AB9 -> 0 | G38: =IF(E38=0,0,((E38-F38)/E38)*100) -> 0 | H38: =E38+B38 -> 0 | I38: =C38+F38 -> 0 | J38: =IF(H38=0,0,((H38-I38)/H38)*100) -> 0 | K38: 0 | L38: 0 | M38: =IF(K38=0,0,((K38-L38)/K38)*100) -> 0 | N38: =Resources!AE9 -> 0 | O38: =Resources!AG9 -> 0 | P38: =IF(N38=0,0,((N38-O38)/N38)*100) -> 0 | Q38: =N38+K38 -> 0 | R38: =L38+O38 -> 0 | S38: =IF(Q38=0,0,((Q38-R38)/Q38)*100) -> 0
A39: L7 | D39: =IF(B39=0,0,((B39-C39)/B39)*100) -> 0 | E39: =Resources!Z10 -> 0 | F39: =Resources!AB10 -> 0 | G39: =IF(E39=0,0,((E39-F39)/E39)*100) -> 0 | H39: =E39+B39 -> 0 | I39: =C39+F39 -> 0 | J39: =IF(H39=0,0,((H39-I39)/H39)*100) -> 0 | K39: 0 | L39: 0 | M39: =IF(K39=0,0,((K39-L39)/K39)*100) -> 0 | N39: =Resources!AE10 -> 0 | O39: =Resources!AG10 -> 0 | P39: =IF(N39=0,0,((N39-O39)/N39)*100) -> 0 | Q39: =N39+K39 -> 0 | R39: =L39+O39 -> 0 | S39: =IF(Q39=0,0,((Q39-R39)/Q39)*100) -> 0
A40: L8 | D40: =IF(B40=0,0,((B40-C40)/B40)*100) -> 0 | E40: =Resources!Z11 -> 0 | F40: =Resources!AB11 -> 0 | G40: =IF(E40=0,0,((E40-F40)/E40)*100) -> 0 | H40: =E40+B40 -> 0 | I40: =C40+F40 -> 0 | J40: =IF(H40=0,0,((H40-I40)/H40)*100) -> 0 | K40: 0 | L40: 0 | M40: =IF(K40=0,0,((K40-L40)/K40)*100) -> 0 | N40: =Resources!AE11 -> 0 | O40: =Resources!AG11 -> 0 | P40: =IF(N40=0,0,((N40-O40)/N40)*100) -> 0 | Q40: =N40+K40 -> 0 | R40: =L40+O40 -> 0 | S40: =IF(Q40=0,0,((Q40-R40)/Q40)*100) -> 0
A41: L9 | D41: =IF(B41=0,0,((B41-C41)/B41)*100) -> 0 | E41: =Resources!Z12 -> 0 | F41: =Resources!AB12 -> 0 | G41: =IF(E41=0,0,((E41-F41)/E41)*100) -> 0 | H41: =E41+B41 -> 0 | I41: =C41+F41 -> 0 | J41: =IF(H41=0,0,((H41-I41)/H41)*100) -> 0 | K41: 0 | L41: 0 | M41: =IF(K41=0,0,((K41-L41)/K41)*100) -> 0 | N41: =Resources!AE12 -> 0 | O41: =Resources!AG12 -> 0 | P41: =IF(N41=0,0,((N41-O41)/N41)*100) -> 0 | Q41: =N41+K41 -> 0 | R41: =L41+O41 -> 0 | S41: =IF(Q41=0,0,((Q41-R41)/Q41)*100) -> 0
A42: L10 | D42: =IF(B42=0,0,((B42-C42)/B42)*100) -> 0 | E42: =Resources!Z13 -> 0 | F42: =Resources!AB13 -> 0 | G42: =IF(E42=0,0,((E42-F42)/E42)*100) -> 0 | H42: =E42+B42 -> 0 | I42: =C42+F42 -> 0 | J42: =IF(H42=0,0,((H42-I42)/H42)*100) -> 0 | K42: 4 | L42: 4 | M42: =IF(K42=0,0,((K42-L42)/K42)*100) -> 0 | N42: =Resources!AE13 -> 0 | O42: =Resources!AG13 -> 0 | P42: =IF(N42=0,0,((N42-O42)/N42)*100) -> 0 | Q42: =N42+K42 -> 4 | R42: =L42+O42 -> 4 | S42: =IF(Q42=0,0,((Q42-R42)/Q42)*100) -> 0
A43: Total Project Efforts (Man-Hrs) | B43: =SUM(B33:B42) -> 0 | C43: =SUM(C33:C42) -> 0 | D43: =SUM(D33:D42) -> 0 | E43: =SUM(E33:E42) -> 0 | F43: =SUM(F33:F42) -> 0 | G43: =SUM(G33:G42) -> 0 | H43: =SUM(H33:H42) -> 0 | I43: =SUM(I33:I42) -> 0 | ... S43: =SUM(S33:S42) -> 0
A45: 2. PROJECT SIZE (FP / Other count)
A46: Project Size in FP/ other-Count | C46: Initial | E46: Last Calculated | G46: Current Calculated | I46: Deviation
A47: Value (FP/ Other-Count) | C47: ='Project Info'!B15 -> 0 | E47: ='Project Info'!D15 -> 0 | G47: ='Project Info'!D15 -> 0 | I47: =IF(G47=0,0,100*(G47-C47)/G47) -> 0

Sheet Control Sheet
A1: Resource Type | B1: Type Description | H1: Resource Level | J1: Availibility Status | L1: Issue Status | N1: Project Category | P1: Vertical
N2: A | P2: ISV
A3: SEG | B3: Project Team Effort (Man-Hrs) (SEG) | H3: L1 | J3: Not Available | L3: Open | N3: B | P3: CSP
A4: CTT | B4: Testing Team Effort (Man-Hrs) (CTT) | H4: L2 | J4: Resigned | L4: Closed | N4: C | P4: Manufacturing
A5: GRA | B5: Graphics Efforts (Man-Hrs) (GRA) | H5: L3 | J5: Available | L5: In Progress | N5: D | P5: Retail
A6: TWR | B6: Tech. Writer Efforts (Man-Hrs) (TWR) | H6: L4 | P6: FS
A7: QAG | B7: QAG Efforts (Man-Hrs) (QAG) | H7: L5 | P7: Emerging Business
A8: ORG | B8: Organizational Efforts (Man-Hrs) (ORG) | H8: L6 | P8: SSDG
A9: PMS | B9: PM Efforts (Man-Hrs) (PMS) | H9: L7 | P9: Public Sector
A10: ARC | B10: Architecture (Man-Hrs) (ARC) | H10: L8
A11: BAS | B11: Business Analyst Efforts (Man-Hrs) (BAS) | H11: L9
A12: PMO | B12: PMO Efforts (Man-Hrs) (PMO) | H12: L10

Sheet Training
A1: S. No. | B1: Training Requirement | C1: Type of training | D1: No. of people to be trained | E1: People to be trained (names) | F1: People trained (names) | G1: Training completion date | H1: Training effort in person hours | I1: Status | J1: Remarks

Sheet Resources
A1: Current Manpower Status Report ( Resource Type Wise) | T1: Current Manpower Status Report ( Resource Level Wise)
A2: Effort Type(Man-hours) | G2: Offshore | K2: Deviation (%) | L2: Onsite | O2: Deviation (%) | T2: Resource Level (Man-hours) | Z2: Offshore | AD2: Deviation (%) | AE2: Onsite | AH2: Deviation (%)
G3: Planned | I3: Actual | L3: Planned | N3: Actual | Z3: Planned | AB3: Actual | AE3: Planned | AG3: Actual
A4: Project Team Effort (Man-Hrs) (SEG) | G4: =SUMIF($G$18:$G$86,"SEG",$H$18:$H$86) -> 0 | I4: =SUMIF($G$18:$G$86,"SEG",$J$18:$J$86) -> 0 | K4: =IF(G4=0,"",100*(G4-I4)/G4) | L4: =SUMIF($G$18:$G$86,"SEG",$L$18:$L$86) -> 0 | N4: =SUMIF($G$18:$G$86,"SEG",$N$18:$N$86) -> 0 | O4: =IF(L4=0,"",100*(L4-N4)/L4) | T4: L1 | Z4: =SUMIF($F$18:$F$86,"L1",$H$18:$H$86) -> 0 | AB4: =SUMIF($F$18:$F$86,"L1",$J$18:$J$86) -> 0 | AD4: =IF(Z4=0,"",100*(Z4-AB4)/Z4) | AE4: =SUMIF($F$18:$F$86,"L1",$L$18:$L$86) -> 0 | AG4: =SUMIF($F$18:$F$86,"L1",$N$18:$N$86) -> 0 | AH4: =IF(AE4=0,"",100*(AE4-AG4)/AE4)
A5: Testing Team Effort (Man-Hrs) (CTT) | G5: =SUMIF($G$18:$G$86,"CTT",$H$18:$H$86) -> 0 | I5: =SUMIF($G$18:$G$86,"CTT",$J$18:$J$86) -> 0 | K5: =IF(G5=0,"",100*(G5-I5)/G5) | L5: =SUMIF($G$18:$G$86,"CTT",$L$18:$L$86) -> 0 | N5: =SUMIF($G$18:$G$86,"CTT",$N$18:$N$86) -> 0 | O5: =IF(L5=0,"",100*(L5-N5)/L5) | T5: L2 | Z5: =SUMIF($F$18:$F$86,"L2",$H$18:$H$86) -> 0 | AB5: =SUMIF($F$18:$F$86,"L2",$J$18:$J$86) -> 0 | AD5: =IF(Z5=0,"",100*(Z5-AB5)/Z5) | AE5: =SUMIF($F$18:$F$86,"L2",$L$18:$L$86) -> 0 | AG5: =SUMIF($F$18:$F$86,"L2",$N$18:$N$86) -> 0 | AH5: =IF(AE5=0,"",100*(AE5-AG5)/AE5)
A6: Graphics Efforts (Man-Hrs) (GRA) | G6: =SUMIF($G$18:$G$86,"GRA",$H$18:$H$86) -> 0 | I6: =SUMIF($G$18:$G$86,"GRA",$J$18:$J$86) -> 0 | K6: =IF(G6=0,"",100*(G6-I6)/G6) | L6: =SUMIF($G$18:$G$86,"GRA",$L$18:$L$86) -> 0 | N6: =SUMIF($G$18:$G$86,"GRA",$N$18:$N$86) -> 0 | O6: =IF(L6=0,"",100*(L6-N6)/L6) | T6: L3 | Z6: =SUMIF($F$18:$F$86,"L3",$H$18:$H$86) -> 0 | AB6: =SUMIF($F$18:$F$86,"L3",$J$18:$J$86) -> 0 | AD6: =IF(Z6=0,"",100*(Z6-AB6)/Z6) | AE6: =SUMIF($F$18:$F$86,"L3",$L$18:$L$86) -> 0 | AG6: =SUMIF($F$18:$F$86,"L3",$N$18:$N$86) -> 0 | AH6: =IF(AE6=0,"",100*(AE6-AG6)/AE6)
A7: Tech. Writer Efforts (Man-Hrs) (TWR) | G7: =SUMIF($G$18:$G$86,"TWR",$H$18:$H$86) -> 0 | I7: =SUMIF($G$18:$G$86,"TWR",$J$18:$J$86) -> 0 | K7: =IF(G7=0,"",100*(G7-I7)/G7) | L7: =SUMIF($G$18:$G$86,"TWR",$L$18:$L$86) -> 0 | N7: =SUMIF($G$18:$G$86,"TWR",$N$18:$N$86) -> 0 | O7: =IF(L7=0,"",100*(L7-N7)/L7) | T7: L4 | Z7: =SUMIF($F$18:$F$86,"L4",$H$18:$H$86) -> 0 | AB7: =SUMIF($F$18:$F$86,"L4",$J$18:$J$86) -> 0 | AD7: =IF(Z7=0,"",100*(Z7-AB7)/Z7) | AE7: =SUMIF($F$18:$F$86,"L4",$L$18:$L$86) -> 0 | AG7: =SUMIF($F$18:$F$86,"L4",$N$18:$N$86) -> 0 | AH7: =IF(AE7=0,"",100*(AE7-AG7)/AE7)
A8: QAG Efforts (Man-Hrs) (QAG) | G8: =SUMIF($G$18:$G$86,"QAG",$H$18:$H$86) -> 0 | I8: =SUMIF($G$18:$G$86,"QAG",$J$18:$J$86) -> 0 | K8: =IF(G8=0,"",100*(G8-I8)/G8) | L8: =SUMIF($G$18:$G$86,"QAG",$L$18:$L$86) -> 0 | N8: =SUMIF($G$18:$G$86,"QAG",$N$18:$N$86) -> 0 | O8: =IF(L8=0,"",100*(L8-N8)/L8) | T8: L5 | Z8: =SUMIF($F$18:$F$86,"L5",$H$18:$H$86) -> 0 | AB8: =SUMIF($F$18:$F$86,"L5",$J$18:$J$86) -> 0 | AD8: =IF(Z8=0,"",100*(Z8-AB8)/Z8) | AE8: =SUMIF($F$18:$F$86,"L5",$L$18:$L$86) -> 0 | AG8: =SUMIF($F$18:$F$86,"L5",$N$18:$N$86) -> 0 | AH8: =IF(AE8=0,"",100*(AE8-AG8)/AE8) | AK8: Resource Type | AL8: Type Description | AR8: Resource Level | AT8: Availibility Status
A9: Organizational Efforts (Man-Hrs) (ORG) | G9: =SUMIF($G$18:$G$86,"ORG",$H$18:$H$86) -> 0 | I9: =SUMIF($G$18:$G$86,"ORG",$J$18:$J$86) -> 0 | K9: =IF(G9=0,"",100*(G9-I9)/G9) | L9: =SUMIF($G$18:$G$86,"ORG",$L$18:$L$86) -> 0 | N9: =SUMIF($G$18:$G$86,"ORG",$N$18:$N$86) -> 0 | O9: =IF(L9=0,"",100*(L9-N9)/L9) | T9: L6 | Z9: =SUMIF($F$18:$F$86,"L6",$H$18:$H$86) -> 0 | AB9: =SUMIF($F$18:$F$86,"L6",$J$18:$J$86) -> 0 | AD9: =IF(Z9=0,"",100*(Z9-AB9)/Z9) | AE9: =SUMIF($F$18:$F$86,"L6",$L$18:$L$86) -> 0 | AG9: =SUMIF($F$18:$F$86,"L6",$N$18:$N$86) -> 0 | AH9: =IF(AE9=0,"",100*(AE9-AG9)/AE9)
A10: PM Efforts (Man-Hrs) (PMS) | G10: =SUMIF($G$18:$G$86,"PMS",$H$18:$H$86) -> 0 | I10: =SUMIF($G$18:$G$86,"PMS",$J$18:$J$86) -> 0 | K10: =IF(G10=0,"",100*(G10-I10)/G10) | L10: =SUMIF($G$18:$G$86,"PMS",$L$18:$L$86) -> 0 | N10: =SUMIF($G$18:$G$86,"PMS",$N$18:$N$86) -> 0 | O10: =IF(L10=0,"",100*(L10-N10)/L10) | T10: L7 | Z10: =SUMIF($F$18:$F$86,"L7",$H$18:$H$86) -> 0 | AB10: =SUMIF($F$18:$F$86,"L7",$J$18:$J$86) -> 0 | AD10: =IF(Z10=0,"",100*(Z10-AB10)/Z10) | AE10: =SUMIF($F$18:$F$86,"L7",$L$18:$L$86) -> 0 | AG10: =SUMIF($F$18:$F$86,"L7",$N$18:$N$86) -> 0 | AH10: =IF(AE10=0,"",100*(AE10-AG10)/AE10) | AK10: SEG | AL10: Project Team Effort (Man-Hrs) (SEG) | AR10: L1 | AT10: Not Available
A11: Architecture (Man-Hrs) (ARC) | G11: =SUMIF($G$18:$G$86,"ARC",$H$18:$H$86) -> 0 | I11: =SUMIF($G$18:$G$86,"ARC",$J$18:$J$86) -> 0 | K11: =IF(G11=0,"",100*(G11-I11)/G11) | L11: =SUMIF($G$18:$G$86,"ARC",$L$18:$L$86) -> 0 | N11: =SUMIF($G$18:$G$86,"ARC",$N$18:$N$86) -> 0 | O11: =IF(L11=0,"",100*(L11-N11)/L11) | T11: L8 | Z11: =SUMIF($F$18:$F$86,"L8",$H$18:$H$86) -> 0 | AB11: =SUMIF($F$18:$F$86,"L8",$J$18:$J$86) -> 0 | AD11: =IF(Z11=0,"",100*(Z11-AB11)/Z11) | AE11: =SUMIF($F$18:$F$86,"L8",$L$18:$L$86) -> 0 | AG11: =SUMIF($F$18:$F$86,"L8",$N$18:$N$86) -> 0 | AH11: =IF(AE11=0,"",100*(AE11-AG11)/AE11) | AK11: CTT | AL11: Testing Team Effort (Man-Hrs) (CTT) | AR11: L2 | AT11: Resigned
A12: Business Analyst Efforts (Man-Hrs) (BAS) | G12: =SUMIF($G$18:$G$86,"BAS",$H$18:$H$86) -> 0 | I12: =SUMIF($G$18:$G$86,"BAS",$J$18:$J$86) -> 0 | K12: =IF(G12=0,"",100*(G12-I12)/G12) | L12: =SUMIF($G$18:$G$86,"BAS",$L$18:$L$86) -> 0 | N12: =SUMIF($G$18:$G$86,"BAS",$N$18:$N$86) -> 0 | O12: =IF(L12=0,"",100*(L12-N12)/L12) | T12: L9 | Z12: =SUMIF($F$18:$F$86,"L9",$H$18:$H$86) -> 0 | AB12: =SUMIF($F$18:$F$86,"L9",$J$18:$J$86) -> 0 | AD12: =IF(Z12=0,"",100*(Z12-AB12)/Z12) | AE12: =SUMIF($F$18:$F$86,"L9",$L$18:$L$86) -> 0 | AG12: =SUMIF($F$18:$F$86,"L9",$N$18:$N$86) -> 0 | AH12: =IF(AE12=0,"",100*(AE12-AG12)/AE12) | AK12: GRA | AL12: Graphics Efforts (Man-Hrs) (GRA) | AR12: L3 | AT12: Available
A13: PMO Efforts (Man-Hrs) (PMO) | G13: =SUMIF($G$18:$G$86,"PMO",$H$18:$H$86) -> 0 | I13: =SUMIF($G$18:$G$86,"PMO",$J$18:$J$86) -> 0 | K13: =IF(G13=0,"",100*(G13-I13)/G13) | L13: =SUMIF($G$18:$G$86,"PMO",$L$18:$L$86) -> 0 | N13: =SUMIF($G$18:$G$29,"PMO",$N$18:$N$29) -> 0 | O13: =IF(L13=0,"",100*(L13-N13)/L13) | T13: L10 | Z13: =SUMIF($F$18:$F$86,"L10",$H$18:$H$86) -> 0 | AB13: =SUMIF($F$18:$F$86,"L10",$J$18:$J$86) -> 0 | AD13: =IF(Z13=0,"",100*(Z13-AB13)/Z13) | AE13: =SUMIF($F$18:$F$86,"L10",$L$18:$L$86) -> 0 | AG13: =SUMIF($F$18:$F$86,"L10",$N$18:$N$86) -> 0 | AH13: =IF(AE13=0,"",100*(AE13-AG13)/AE13) | AK13: TWR | AL13: Tech. Writer Efforts (Man-Hrs) (TWR) | AR13: L4
A14: Total Project Efforts | G14: =SUM(G4:G13) -> 0 | I14: =SUM(I4:I13) -> 0 | K14: =IF(G14=0,"",100*((G14-I14)/G14)) | L14: =SUM(L4:L13) -> 0 | N14: =SUM(N4:N13) -> 0 | O14: =IF(L14=0,"",100*(L14-N14)/L14) | T14: Total Project Efforts | Z14: =SUM(Z4:Z13) -> 0 | AB14: =SUM(AB4:AB13) -> 0 | AD14: =IF(Z14=0,"",100*((Z14-AB14)/Z14)) | AE14: =SUM(AE4:AE13) -> 0 | AG14: =SUM(AG4:AG13) -> 0 | AH14: =IF(AE14=0,"",100*(AE14-AG14)/AE14) | AK14: QAG | AL14: QAG Efforts (Man-Hrs) (QAG) | AR14: L5
AK15: ORG | AL15: Organizational Efforts (Man-Hrs) (ORG) | AR15: L6
A16: Employee Code | B16: Name of Resource | F16: Level | G16: Type | H16: Offshore Effort (Current Month) | K16: Deviation (%) | L16: Onsite (Current Month) | O16: Deviation (%) | P16: Availibility Status | T16: %Billable (Planned in Current Month) | Z16: %Billable (Actual in Current Month) | AK16: PMS | AL16: PM Efforts (Man-Hrs) (PMS) | AR16: L7
H17: Effort Planned | J17: Effort Spent | K17: Deviation (%) | L17: Effort Planned | N17: Effort Spent | O17: Deviation (%) | AK17: ARC | AL17: Architecture (Man-Hrs) (ARC) | AR17: L8
K18: =IF(H18="","",100*((H18-J18)/H18)) | O18: =IF(L18="","",100*((L18-N18)/L18)) | P18: Available | Q18: =IF(P18<>"Available ",0,1) -> 0 | R18: =IF(P18<>"Resigned",0,1) -> 0 | S18: =IF(P18<>"Not Available",0,1) -> 0 | T18: =(H18+L18)*100/160 -> 0 | Z18: =(J18+N18)*100/160 -> 0 | AK18: BAS | AL18: Business Analyst Efforts (Man-Hrs) (BAS) | AR18: L9
K19: =IF(H19="","",100*((H19-J19)/H19)) | O19: =IF(L19="","",100*((L19-N19)/L19)) | P19: Available | Q19: =IF(P19<>"Available ",0,1) -> 0 | R19: =IF(P19<>"Resigned",0,1) -> 0 | S19: =IF(P19<>"Not Available",0,1) -> 0 | T19: =(H19+L19)*100/160 -> 0 | Z19: =(J19+N19)*100/160 -> 0 | AK19: PMO | AL19: PMO Efforts (Man-Hrs) (PMO) | AR19: L10
K20: =IF(H20="","",100*((H20-J20)/H20)) | O20: =IF(L20="","",100*((L20-N20)/L20)) | P20: Available | Q20: =IF(P20<>"Available ",0,1) -> 0 | R20: =IF(P20<>"Resigned",0,1) -> 0 | S20: =IF(P20<>"Not Available",0,1) -> 0 | T20: =(H20+L20)*100/160 -> 0 | Z20: =(J20+N20)*100/160 -> 0
K21: =IF(H21="","",100*((H21-J21)/H21)) | O21: =IF(L21="","",100*((L21-N21)/L21)) | P21: Available | Q21: =IF(P21<>"Available ",0,1) -> 0 | R21: =IF(P21<>"Resigned",0,1) -> 0 | S21: =IF(P21<>"Not Available",0,1) -> 0 | T21: =(H21+L21)*100/160 -> 0 | Z21: =(J21+N21)*100/160 -> 0
K22: =IF(H22="","",100*((H22-J22)/H22)) | O22: =IF(L22="","",100*((L22-N22)/L22)) | P22: Available | Q22: =IF(P22<>"Available ",0,1) -> 0 | R22: =IF(P22<>"Resigned",0,1) -> 0 | S22: =IF(P22<>"Not Available",0,1) -> 0 | T22: =(H22+L22)*100/160 -> 0 | Z22: =(J22+N22)*100/160 -> 0
K23: =IF(H23="","",100*((H23-J23)/H23)) | O23: =IF(L23="","",100*((L23-N23)/L23)) | P23: Available | Q23: =IF(P23<>"Available ",0,1) -> 0 | R23: =IF(P23<>"Resigned",0,1) -> 0 | S23: =IF(P23<>"Not Available",0,1) -> 0 | T23: =(H23+L23)*100/160 -> 0 | Z23: =(J23+N23)*100/160 -> 0
K24: =IF(H24="","",100*((H24-J24)/H24)) | O24: =IF(L24="","",100*((L24-N24)/L24)) | P24: Available | Q24: =IF(P24<>"Available ",0,1) -> 0 | R24: =IF(P24<>"Resigned",0,1) -> 0 | S24: =IF(P24<>"Not Available",0,1) -> 0 | T24: =(H24+L24)*100/160 -> 0 | Z24: =(J24+N24)*100/160 -> 0
K25: =IF(H25="","",100*((H25-J25)/H25)) | O25: =IF(L25="","",100*((L25-N25)/L25)) | P25: Available | Q25: =IF(P25<>"Available ",0,1) -> 0 | R25: =IF(P25<>"Resigned",0,1) -> 0 | S25: =IF(P25<>"Not Available",0,1) -> 0 | T25: =(H25+L25)*100/160 -> 0 | Z25: =(J25+N25)*100/160 -> 0
K26: =IF(H26="","",100*((H26-J26)/H26)) | O26: =IF(L26="","",100*((L26-N26)/L26)) | P26: Available | Q26: =IF(P26<>"Available ",0,1) -> 0 | R26: =IF(P26<>"Resigned",0,1) -> 0 | S26: =IF(P26<>"Not Available",0,1) -> 0 | T26: =(H26+L26)*100/160 -> 0 | Z26: =(J26+N26)*100/160 -> 0
K27: =IF(H27="","",100*((H27-J27)/H27)) | O27: =IF(L27="","",100*((L27-N27)/L27)) | P27: Available | Q27: =IF(P27<>"Available ",0,1) -> 0 | R27: =IF(P27<>"Resigned",0,1) -> 0 | S27: =IF(P27<>"Not Available",0,1) -> 0 | T27: =(H27+L27)*100/160 -> 0 | Z27: =(J27+N27)*100/160 -> 0
K28: =IF(H28="","",100*((H28-J28)/H28)) | O28: =IF(L28="","",100*((L28-N28)/L28)) | P28: Available | Q28: =IF(P28<>"Available ",0,1) -> 0 | R28: =IF(P28<>"Resigned",0,1) -> 0 | S28: =IF(P28<>"Not Available",0,1) -> 0 | T28: =(H28+L28)*100/160 -> 0 | Z28: =(J28+N28)*100/160 -> 0
K29: =IF(H29="","",100*((H29-J29)/H29)) | O29: =IF(L29="","",100*((L29-N29)/L29)) | P29: Available | Q29: =IF(P29<>"Available ",0,1) -> 0 | R29: =IF(P29<>"Resigned",0,1) -> 0 | S29: =IF(P29<>"Not Available",0,1) -> 0 | T29: =(H29+L29)*100/160 -> 0 | Z29: =(J29+N29)*100/160 -> 0
K30: =IF(H30="","",100*((H30-J30)/H30)) | O30: =IF(L30="","",100*((L30-N30)/L30)) | Q30: =IF(P30<>"Available ",0,1) -> 0 | R30: =IF(P30<>"Resigned",0,1) -> 0 | S30: =IF(P30<>"Not Available",0,1) -> 0 | T30: =(H30+L30)*100/160 -> 0 | Z30: =(J30+N30)*100/160 -> 0
K31: =IF(H31="","",100*((H31-J31)/H31)) | O31: =IF(L31="","",100*((L31-N31)/L31)) | Q31: =IF(P31<>"Available ",0,1) -> 0 | R31: =IF(P31<>"Resigned",0,1) -> 0 | S31: =IF(P31<>"Not Available",0,1) -> 0 | T31: =(H31+L31)*100/160 -> 0 | Z31: =(J31+N31)*100/160 -> 0
K32: =IF(H32="","",100*((H32-J32)/H32)) | O32: =IF(L32="","",100*((L32-N32)/L32)) | Q32: =IF(P32<>"Available ",0,1) -> 0 | R32: =IF(P32<>"Resigned",0,1) -> 0 | S32: =IF(P32<>"Not Available",0,1) -> 0 | T32: =(H32+L32)*100/160 -> 0 | Z32: =(J32+N32)*100/160 -> 0
K33: =IF(H33="","",100*((H33-J33)/H33)) | O33: =IF(L33="","",100*((L33-N33)/L33)) | Q33: =IF(P33<>"Available ",0,1) -> 0 | R33: =IF(P33<>"Resigned",0,1) -> 0 | S33: =IF(P33<>"Not Available",0,1) -> 0 | T33: =(H33+L33)*100/160 -> 0 | Z33: =(J33+N33)*100/160 -> 0
K34: =IF(H34="","",100*((H34-J34)/H34)) | O34: =IF(L34="","",100*((L34-N34)/L34)) | Q34: =IF(P34<>"Available ",0,1) -> 0 | R34: =IF(P34<>"Resigned",0,1) -> 0 | S34: =IF(P34<>"Not Available",0,1) -> 0 | T34: =(H34+L34)*100/160 -> 0 | Z34: =(J34+N34)*100/160 -> 0
K35: =IF(H35="","",100*((H35-J35)/H35)) | O35: =IF(L35="","",100*((L35-N35)/L35)) | Q35: =IF(P35<>"Available ",0,1) -> 0 | R35: =IF(P35<>"Resigned",0,1) -> 0 | S35: =IF(P35<>"Not Available",0,1) -> 0 | T35: =(H35+L35)*100/160 -> 0 | Z35: =(J35+N35)*100/160 -> 0
K36: =IF(H36="","",100*((H36-J36)/H36)) | O36: =IF(L36="","",100*((L36-N36)/L36)) | Q36: =IF(P36<>"Available ",0,1) -> 0 | R36: =IF(P36<>"Resigned",0,1) -> 0 | S36: =IF(P36<>"Not Available",0,1) -> 0 | T36: =(H36+L36)*100/160 -> 0 | Z36: =(J36+N36)*100/160 -> 0
K37: =IF(H37="","",100*((H37-J37)/H37)) | O37: =IF(L37="","",100*((L37-N37)/L37)) | Q37: =IF(P37<>"Available ",0,1) -> 0 | R37: =IF(P37<>"Resigned",0,1) -> 0 | S37: =IF(P37<>"Not Available",0,1) -> 0 | T37: =(H37+L37)*100/160 -> 0 | Z37: =(J37+N37)*100/160 -> 0
K38: =IF(H38="","",100*((H38-J38)/H38)) | O38: =IF(L38="","",100*((L38-N38)/L38)) | Q38: =IF(P38<>"Available ",0,1) -> 0 | R38: =IF(P38<>"Resigned",0,1) -> 0 | S38: =IF(P38<>"Not Available",0,1) -> 0 | T38: =(H38+L38)*100/160 -> 0 | Z38: =(J38+N38)*100/160 -> 0
K39: =IF(H39="","",100*((H39-J39)/H39)) | O39: =IF(L39="","",100*((L39-N39)/L39)) | Q39: =IF(P39<>"Available ",0,1) -> 0 | R39: =IF(P39<>"Resigned",0,1) -> 0 | S39: =IF(P39<>"Not Available",0,1) -> 0 | T39: =(H39+L39)*100/160 -> 0 | Z39: =(J39+N39)*100/160 -> 0
K40: =IF(H40="","",100*((H40-J40)/H40)) | O40: =IF(L40="","",100*((L40-N40)/L40)) | Q40: =IF(P40<>"Available ",0,1) -> 0 | R40: =IF(P40<>"Resigned",0,1) -> 0 | S40: =IF(P40<>"Not Available",0,1) -> 0 | T40: =(H40+L40)*100/160 -> 0 | Z40: =(J40+N40)*100/160 -> 0
...

Sheet Metrics planning and tracking
A1: Id. | B1: Objective | C1: Source of Objective | D1: Metric | E1: Unit | F1: Required measures | G1: Definition | H1: Priority | I1: Organization baseline (if applicable) | J1: SDC / Centre baseline | K1: Project Goal | L1: Upper specification limit | M1: Lower specification limit | N1: Current Value | O1: Analysis model / methodologies | P1: Tracking remarks
A2: 1 | B2: Improve Delivery Variances | C2: Organizational Measurement Objectives | D2: Effort Variation - Initial | E2: % | F2: Initial effort estimated and Actual effort | G2: (Actual effort - Estimated effort) x 100 Estimated effort | H2: Medium | I2: 0.1 | J2: 0.1 | K2: 10 | L2: 15 | M2: 0 | N2: =IF(S2<>0,IF(U2<>0,(U2-S2)/S2%,"Not Available"),"Not Available") -> Not Available | S2: =SUMIF('Size, Schedule and Effort'!O3:O496,"Completed",'Size, Schedule and Effort'!H3:H496) -> 0 | T2: =SUMIF('Size, Schedule and Effort'!O3:O496,"Completed",'Size, Schedule and Effort'!W3:W496) -> 0 | U2: =SUMIF('Size, Schedule and Effort'!O3:O496,"Completed",'Size, Schedule and Effort'!J3:J496) -> 0
A3: 2 | B3: Improve Delivery Variances | C3: Organizational Measurement Objectives | D3: Effort Variation - Baselined | E3: % | F3: Last baselined effort estimate and Actual effort | G3: (Actual effort - Baselined effort) x 100 Baslined effort | H3: High | I3: 0.05 | J3: 0.05 | K3: 5 | L3: 10 | M3: 0 | N3: =IF(T2<>0,IF(U2<>0,(U2-T2)/T2%,"Not Available"),"Not Available") -> Not Available
A4: 3 | B4: Improve Delivery Variances | C4: Organizational Measurement Objectives | D4: Schedule Variation - Initial | E4: % | F4: Schedule | G4: (Actual completion date - Estimated completion date) x 100 / (Estimated duration) | H4: Medium | I4: 0.1 | J4: 0.1 | K4: 10 | L4: 15 | M4: 0 | N4: {=IF(COUNT('Project information1'!D2:D3,'Project information1'!D6:D7)<4,IF(COUNT('Size, Schedule and Effort'!K$3:K$496)>0,MAX(IF('Size, Schedule and Effort'!G$3:G$496 = MAX('Size, Schedule and Effort'!G$3:G$496),'Size, Schedule and Effort'!K$3:K$496,"")),"Not Available"),('Project information1'!D7-'Project information1'!D3)/('Project information1'!D3-'Project information1'!D2+1)*100)} -> Not Available
A5: 4 | B5: Improve Delivery Variances | C5: Organizational Measurement Objectives | D5: Schedule Variation - Baselined | E5: % | F5: Schedule | G5: (Actual completion date - Last Baselined completion date) x 100 / (Last baselined duration) | H5: High | I5: 0.05 | J5: 0.05 | K5: 5 | L5: 10 | M5: 0 | N5: {=IF(COUNT('Project information1'!D4:D5,'Project information1'!D6:D7)<4,IF(COUNT('Size, Schedule and Effort'!L$3:L$496)>0,MAX(IF('Size, Schedule and Effort'!G$3:G$496 = MAX('Size, Schedule and Effort'!G$3:G$496),'Size, Schedule and Effort'!L$3:L$496,"")),"Not Available"),('Project information1'!D7-'Project information1'!D5)/('Project information1'!D5-'Project information1'!D4+1)*100)} -> Not Available
A6: 5 | B6: Improve Productivity and reduce Cost of Software Production | C6: Organizational Measurement Objectives | D6: Productivity | E6: ='Project information1'!B13 & " / " & 'Project information1'!D11 -> / | F6: Actual Size and effort data | G6: Actual Size Actual Effort | H6: High | I6: 0.17 | J6: 0.17 | K6: 0.16 | L6: 0.18 | M6: 0.15 | N6: =IF('Project information1'!B16<>"",IF(AND('Project information1'!B150<>"",'Project information1'!D10<>0),'Project information1'!B16/'Project information1'!B15,"NA"),"Not Available") -> Not Available
A7: 6 | B7: Reduce Pre and Post Delivery Defects in all Deliveries | C7: Organizational Measurement Objectives | D7: Weighted Defect density | E7: ="Weighted defects / " & 'Project information1'!B13 -> Weighted defects / | F7: Actual Size, Review issues and test defects | G7: Total Weighted Defects found / Actual project size | H7: High | I7: 0.002 | J7: 0.002 | K7: 0.002 | L7: 0.003 | M7: 0 | N7: =IF(AND(SUM(S7:X7)>0,Y7<>"NA"),((S7+V7)+0.33*(T7+W7)+0.2*(U7+X7))/(Y7),"Not Available") -> #REF! | S7: =SUM('Verification Summary'!E10:E24) -> 0 | T7: =SUM('Verification Summary'!F10:F24) -> 0 | U7: =SUM('Verification Summary'!G10:G24) -> 0 | V7: =SUM('Verification Summary'!K10:K24) -> 0 | W7: =SUM('Verification Summary'!L10:L24) -> 0 | X7: =SUM('Verification Summary'!M10:M24) -> 0 | Y7: =IF('Project information1'!B12<>"",'Project information1'!B12,IF('Project information1'!B11<>"",'Project information1'!B11,IF('Project information1'!B10<>"",'Project information1'!B10,"NA"))) -> #REF! | Z7: =IF('Project information1'!B12<>"","A",IF('Project information1'!B11<>"","R",IF('Project information1'!B10<>"","P","NA"))) -> #REF!
A8: 7 | B8: Reduce Pre and Post Delivery Defects in all Deliveries | C8: Organizational Measurement Objectives | D8: Review efficiency | E8: % | F8: Total review issues and testing issues | G8: [(No. of Weighted Defects found in Review) / Total No. of Weighted Defects found before Delivery (both Reviews and Testing) ]* 100 | H8: High | I8: 0.7 | J8: 0.7 | K8: 0.7 | L8: 0.95 | M8: 0.6 | N8: =IF(SUM(S7:X7)>0,(1*S7+0.33*T7+0.2*U7)/(1*(S7+V7)+0.33*(T7+W7)+0.2*(U7+X7))%,"Not Available") -> Not Available
A9: 8 | B9: Reduce Pre and Post Delivery Defects in all Deliveries | C9: Organizational Measurement Objectives | D9: Defect removal efficiency | E9: % | F9: Defects detected before release and post release defects | G9: DRE= (E/ E+D) x 100 where E = weighted Pre-delivery errors (detected during all QC / QA) activities D= weighted Post –delivery Defects | H9: High | I9: 0.9 | J9: 0.9 | K9: 0.9 | L9: 1 | M9: 0.8 | N9: =IF(SUM(S7:X7,S9:X9)>0,(1*(S7+V7)+0.33*(T7+W7)+0.2*(U7+X7))/(1*(S7+V7+S9+V9)+0.33*(T7+W7+T9+W9)+0.2*(U7+X7+U9+X9))*100,"Not Available") -> Not Available | S9: =SUM('Verification Summary'!E29:E43) -> 0 | T9: =SUM('Verification Summary'!F29:F43) -> 0 | U9: =SUM('Verification Summary'!G29:G43) -> 0 | V9: =SUM('Verification Summary'!K29:K43) -> 0 | W9: =SUM('Verification Summary'!L29:L43) -> 0 | X9: =SUM('Verification Summary'!M29:M43) -> 0

Sheet Risk Management
J1: Initial | R1: Current
A2: Date identified | B2: Risk Category | C2: Risk Source | D2: Process where Identified | E2: Risk Title | F2: Risk description | G2: Relevant ISMS Control | H2: Relevance (ISMS, QMS, Both) | I2: Owner | J2: Probability | K2: Impact on Cost | L2: Impact on Schedule | M2: Impact on Scope | N2: Impact on Quality | O2: Regulatory Impact | P2: Normalized Impact | Q2: Risk Index - Initial | R2: Probability | S2: Impact on Cost | T2: Impact on Schedule | U2: Impact on Scope | V2: Impact on Quality | W2: Regulatory Impact | X2: Normalized Impact | Y2: Risk Index - Current | Z2: Risk Treatment Plan (Accept, Mitigate, Avoid, Transfer) | AA2: Cost of Risk | AB2: Cost of Mitigation Plan | AC2: Cost / Benefit ratio | AD2: Escalation threshold | AE2: Mitigation plan | AF2: Contingency plan | AG2: External (Impacts customer) / Internal | AH2: Remarks | AI2: Update date | AJ2: Status | AK2: Rev Prob | AL2: Rev Impact | AM2: Rev Risk index | AN2: Status-1
AK3: =IF(R3<>"",R3,IF(J3,J3,"")) | AL3: =IF(X3<>"",X3,IF(P3=1,P3,"")) | AM3: =IF(Y3<>"",Y3,IF(Q3=1,Q3,"")) | AN3: =IF(COUNT(AK3:AM3)>2,IF(AJ3<>"",IF(ISERROR(SEARCH("open",AJ3,1)),"Closed","Open"),"Open"),"") | AP3: =IF(ISERROR(SMALL(#REF!,ROW()-2)),"",INDIRECT("'Control panel'!A" & SMALL(#REF!,ROW()-2),1))
AK4: =IF(R4<>"",R4,IF(J4,J4,"")) | AL4: =IF(X4<>"",X4,IF(P4=1,P4,"")) | AM4: =IF(Y4<>"",Y4,IF(Q4=1,Q4,"")) | AN4: =IF(COUNT(AK4:AM4)>2,IF(AJ4<>"",IF(ISERROR(SEARCH("open",AJ4,1)),"Closed","Open"),"Open"),"") | AP4: =IF(ISERROR(SMALL(#REF!,ROW()-2)),"",INDIRECT("'Control panel'!A" & SMALL(#REF!,ROW()-2),1))
AK5: =IF(R5<>"",R5,IF(J5,J5,"")) | AL5: =IF(X5<>"",X5,IF(P5=1,P5,"")) | AM5: =IF(Y5<>"",Y5,IF(Q5=1,Q5,"")) | AN5: =IF(COUNT(AK5:AM5)>2,IF(AJ5<>"",IF(ISERROR(SEARCH("open",AJ5,1)),"Closed","Open"),"Open"),"") | AP5: =IF(ISERROR(SMALL(#REF!,ROW()-2)),"",INDIRECT("'Control panel'!A" & SMALL(#REF!,ROW()-2),1))
AK6: =IF(R6<>"",R6,IF(J6,J6,"")) | AL6: =IF(X6<>"",X6,IF(P6=1,P6,"")) | AM6: =IF(Y6<>"",Y6,IF(Q6=1,Q6,"")) | AN6: =IF(COUNT(AK6:AM6)>2,IF(AJ6<>"",IF(ISERROR(SEARCH("open",AJ6,1)),"Closed","Open"),"Open"),"") | AP6: =IF(ISERROR(SMALL(#REF!,ROW()-2)),"",INDIRECT("'Control panel'!A" & SMALL(#REF!,ROW()-2),1))
AK7: =IF(R7<>"",R7,IF(J7,J7,"")) | AL7: =IF(X7<>"",X7,IF(P7=1,P7,"")) | AM7: =IF(Y7<>"",Y7,IF(Q7=1,Q7,"")) | AN7: =IF(COUNT(AK7:AM7)>2,IF(AJ7<>"",IF(ISERROR(SEARCH("open",AJ7,1)),"Closed","Open"),"Open"),"") | AP7: =IF(ISERROR(SMALL(#REF!,ROW()-2)),"",INDIRECT("'Control panel'!A" & SMALL(#REF!,ROW()-2),1))
AK8: =IF(R8<>"",R8,IF(J8,J8,"")) | AL8: =IF(X8<>"",X8,IF(P8=1,P8,"")) | AM8: =IF(Y8<>"",Y8,IF(Q8=1,Q8,"")) | AN8: =IF(COUNT(AK8:AM8)>2,IF(AJ8<>"",IF(ISERROR(SEARCH("open",AJ8,1)),"Closed","Open"),"Open"),"") | AP8: =IF(ISERROR(SMALL(#REF!,ROW()-2)),"",INDIRECT("'Control panel'!A" & SMALL(#REF!,ROW()-2),1))
AK9: =IF(R9<>"",R9,IF(J9,J9,"")) | AL9: =IF(X9<>"",X9,IF(P9=1,P9,"")) | AM9: =IF(Y9<>"",Y9,IF(Q9=1,Q9,"")) | AN9: =IF(COUNT(AK9:AM9)>2,IF(AJ9<>"",IF(ISERROR(SEARCH("open",AJ9,1)),"Closed","Open"),"Open"),"") | AP9: =IF(ISERROR(SMALL(#REF!,ROW()-2)),"",INDIRECT("'Control panel'!A" & SMALL(#REF!,ROW()-2),1))
AK10: =IF(R10<>"",R10,IF(J10,J10,"")) | AL10: =IF(X10<>"",X10,IF(P10=1,P10,"")) | AM10: =IF(Y10<>"",Y10,IF(Q10=1,Q10,"")) | AN10: =IF(COUNT(AK10:AM10)>2,IF(AJ10<>"",IF(ISERROR(SEARCH("open",AJ10,1)),"Closed","Open"),"Open"),"") | AP10: =IF(ISERROR(SMALL(#REF!,ROW()-2)),"",INDIRECT("'Control panel'!A" & SMALL(#REF!,ROW()-2),1))
AK11: =IF(R11<>"",R11,IF(J11,J11,"")) | AL11: =IF(X11<>"",X11,IF(P11=1,P11,"")) | AM11: =IF(Y11<>"",Y11,IF(Q11=1,Q11,"")) | AN11: =IF(COUNT(AK11:AM11)>2,IF(AJ11<>"",IF(ISERROR(SEARCH("open",AJ11,1)),"Closed","Open"),"Open"),"") | AP11: =IF(ISERROR(SMALL(#REF!,ROW()-2)),"",INDIRECT("'Control panel'!A" & SMALL(#REF!,ROW()-2),1))
AK12: =IF(R12<>"",R12,IF(J12,J12,"")) | AL12: =IF(X12<>"",X12,IF(P12=1,P12,"")) | AM12: =IF(Y12<>"",Y12,IF(Q12=1,Q12,"")) | AN12: =IF(COUNT(AK12:AM12)>2,IF(AJ12<>"",IF(ISERROR(SEARCH("open",AJ12,1)),"Closed","Open"),"Open"),"") | AP12: =IF(ISERROR(SMALL(#REF!,ROW()-2)),"",INDIRECT("'Control panel'!A" & SMALL(#REF!,ROW()-2),1))
AK13: =IF(R13<>"",R13,IF(J13,J13,"")) | AL13: =IF(X13<>"",X13,IF(P13=1,P13,"")) | AM13: =IF(Y13<>"",Y13,IF(Q13=1,Q13,"")) | AN13: =IF(COUNT(AK13:AM13)>2,IF(AJ13<>"",IF(ISERROR(SEARCH("open",AJ13,1)),"Closed","Open"),"Open"),"") | AP13: =IF(ISERROR(SMALL(#REF!,ROW()-2)),"",INDIRECT("'Control panel'!A" & SMALL(#REF!,ROW()-2),1))
AK14: =IF(R14<>"",R14,IF(J14,J14,"")) | AL14: =IF(X14<>"",X14,IF(P14=1,P14,"")) | AM14: =IF(Y14<>"",Y14,IF(Q14=1,Q14,"")) | AN14: =IF(COUNT(AK14:AM14)>2,IF(AJ14<>"",IF(ISERROR(SEARCH("open",AJ14,1)),"Closed","Open"),"Open"),"") | AP14: =IF(ISERROR(SMALL(#REF!,ROW()-2)),"",INDIRECT("'Control panel'!A" & SMALL(#REF!,ROW()-2),1))
... AK45: =IF(R45<>"",R45,IF(J45,J45,"")) | AL45: =IF(X45<>"",X45,IF(P45=1,P45,"")) | AM45: =IF(Y45<>"",Y45,IF(Q45=1,Q45,"")) | AN45: =IF(COUNT(AK45:AM45)>2,IF(AJ45<>"",IF(ISERROR(SEARCH("open",AJ45,1)),"Closed","Open"),"Open"),"") | AP45: =IF(ISERROR(SMALL(#REF!,ROW()-2)),"",INDIRECT("'Control panel'!A" & SMALL(#REF!,ROW()-2),1))
P46: =IF(COUNT(K46:O46)>0,AVERAGE(K46:O46),"") | Q46: =IF(P46<>"",IF(J46<>"",P46*J46,"Probability?"),"") | X46: =IF(COUNT(S46:W46)>0,AVERAGE(S46:W46),"") | Y46: =IF(X46<>"",IF(R46<>"",X46*R46,"Probability?"),"") | AC46: =IF(AA46<>"",IF(AB46<>"",AB46/AA46,""),"") | AK46: =IF(R46<>"",R46,IF(J46,J46,"")) | AL46: =IF(X46<>"",X46,IF(P46=1,P46,"")) | AM46: =IF(Y46<>"",Y46,IF(Q46=1,Q46,"")) | AN46: =IF(COUNT(AK46:AM46)>2,IF(AJ46<>"",IF(ISERROR(SEARCH("open",AJ46,1)),"Closed","Open"),"Open"),"") | AP46: =IF(ISERROR(SMALL(#REF!,ROW()-2)),"",INDIRECT("'Control panel'!A" & SMALL(#REF!,ROW()-2),1))
P47: =IF(COUNT(K47:O47)>0,AVERAGE(K47:O47),"") | Q47: =IF(P47<>"",IF(J47<>"",P47*J47,"Probability?"),"") | X47: =IF(COUNT(S47:W47)>0,AVERAGE(S47:W47),"") | Y47: =IF(X47<>"",IF(R47<>"",X47*R47,"Probability?"),"") | AK47: =IF(R47<>"",R47,IF(J47,J47,"")) | AL47: =IF(X47<>"",X47,IF(P47=1,P47,"")) | AM47: =IF(Y47<>"",Y47,IF(Q47=1,Q47,"")) | AN47: =IF(COUNT(AK47:AM47)>2,IF(AJ47<>"",IF(ISERROR(SEARCH("open",AJ47,1)),"Closed","Open"),"Open"),"")
P48: =IF(COUNT(K48:O48)>0,AVERAGE(K48:O48),"") | Q48: =IF(P48<>"",IF(J48<>"",P48*J48,"Probability?"),"") | X48: =IF(COUNT(S48:W48)>0,AVERAGE(S48:W48),"") | Y48: =IF(X48<>"",IF(R48<>"",X48*R48,"Probability?"),"") | AK48: =IF(R48<>"",R48,IF(J48,J48,"")) | AL48: =IF(X48<>"",X48,IF(P48=1,P48,"")) | AM48: =IF(Y48<>"",Y48,IF(Q48=1,Q48,"")) | AN48: =IF(COUNT(AK48:AM48)>2,IF(AJ48<>"",IF(ISERROR(SEARCH("open",AJ48,1)),"Closed","Open"),"Open"),"") | AP48: =IF(ISERROR(SMALL(#REF!,ROW()-2)),"",INDIRECT("'Control panel'!A" & SMALL(#REF!,ROW()-2),1))
P49: =IF(COUNT(K49:O49)>0,AVERAGE(K49:O49),"") | Q49: =IF(P49<>"",IF(J49<>"",P49*J49,"Probability?"),"") | X49: =IF(COUNT(S49:W49)>0,AVERAGE(S49:W49),"") | Y49: =IF(X49<>"",IF(R49<>"",X49*R49,"Probability?"),"") | AK49: =IF(R49<>"",R49,IF(J49,J49,"")) | AL49: =IF(X49<>"",X49,IF(P49=1,P49,"")) | AM49: =IF(Y49<>"",Y49,IF(Q49=1,Q49,"")) | AN49: =IF(COUNT(AK49:AM49)>2,IF(AJ49<>"",IF(ISERROR(SEARCH("open",AJ49,1)),"Closed","Open"),"Open"),"")
P50: =IF(COUNT(K50:O50)>0,AVERAGE(K50:O50),"") | Q50: =IF(P50<>"",IF(J50<>"",P50*J50,"Probability?"),"") | X50: =IF(COUNT(S50:W50)>0,AVERAGE(S50:W50),"") | Y50: =IF(X50<>"",IF(R50<>"",X50*R50,"Probability?"),"")
P51: =IF(COUNT(K51:O51)>0,AVERAGE(K51:O51),"") | Q51: =IF(P51<>"",IF(J51<>"",P51*J51,"Probability?"),"") | X51: =IF(COUNT(S51:W51)>0,AVERAGE(S51:W51),"") | Y51: =IF(X51<>"",IF(R51<>"",X51*R51,"Probability?"),"")
P52: =IF(COUNT(K52:O52)>0,AVERAGE(K52:O52),"") | Q52: =IF(P52<>"",IF(J52<>"",P52*J52,"Probability?"),"") | X52: =IF(COUNT(S52:W52)>0,AVERAGE(S52:W52),"") | Y52: =IF(X52<>"",IF(R52<>"",X52*R52,"Probability?"),"")
P53: =IF(COUNT(K53:O53)>0,AVERAGE(K53:O53),"") | Q53: =IF(P53<>"",IF(J53<>"",P53*J53,"Probability?"),"") | X53: =IF(COUNT(S53:W53)>0,AVERAGE(S53:W53),"") | Y53: =IF(X53<>"",IF(R53<>"",X53*R53,"Probability?"),"")
P54: =IF(COUNT(K54:O54)>0,AVERAGE(K54:O54),"") | Q54: =IF(P54<>"",IF(J54<>"",P54*J54,"Probability?"),"") | X54: =IF(COUNT(S54:W54)>0,AVERAGE(S54:W54),"") | Y54: =IF(X54<>"",IF(R54<>"",X54*R54,"Probability?"),"")
P55: =IF(COUNT(K55:O55)>0,AVERAGE(K55:O55),"") | Q55: =IF(P55<>"",IF(J55<>"",P55*J55,"Probability?"),"") | X55: =IF(COUNT(S55:W55)>0,AVERAGE(S55:W55),"") | Y55: =IF(X55<>"",IF(R55<>"",X55*R55,"Probability?"),"")
P56: =IF(COUNT(K56:O56)>0,AVERAGE(K56:O56),"") | Q56: =IF(P56<>"",IF(J56<>"",P56*J56,"Probability?"),"") | X56: =IF(COUNT(S56:W56)>0,AVERAGE(S56:W56),"") | Y56: =IF(X56<>"",IF(R56<>"",X56*R56,"Probability?"),"")
P57: =IF(COUNT(K57:O57)>0,AVERAGE(K57:O57),"") | Q57: =IF(P57<>"",IF(J57<>"",P57*J57,"Probability?"),"") | X57: =IF(COUNT(S57:W57)>0,AVERAGE(S57:W57),"") | Y57: =IF(X57<>"",IF(R57<>"",X57*R57,"Probability?"),"")
P58: =IF(COUNT(K58:O58)>0,AVERAGE(K58:O58),"") | Q58: =IF(P58<>"",IF(J58<>"",P58*J58,"Probability?"),"") | X58: =IF(COUNT(S58:W58)>0,AVERAGE(S58:W58),"") | Y58: =IF(X58<>"",IF(R58<>"",X58*R58,"Probability?"),"")
P59: =IF(COUNT(K59:O59)>0,AVERAGE(K59:O59),"") | Q59: =IF(P59<>"",IF(J59<>"",P59*J59,"Probability?"),"") | X59: =IF(COUNT(S59:W59)>0,AVERAGE(S59:W59),"") | Y59: =IF(X59<>"",IF(R59<>"",X59*R59,"Probability?"),"")
P60: =IF(COUNT(K60:O60)>0,AVERAGE(K60:O60),"") | Q60: =IF(P60<>"",IF(J60<>"",P60*J60,"Probability?"),"") | X60: =IF(COUNT(S60:W60)>0,AVERAGE(S60:W60),"") | Y60: =IF(X60<>"",IF(R60<>"",X60*R60,"Probability?"),"")
P61: =IF(COUNT(K61:O61)>0,AVERAGE(K61:O61),"") | Q61: =IF(P61<>"",IF(J61<>"",P61*J61,"Probability?"),"") | X61: =IF(COUNT(S61:W61)>0,AVERAGE(S61:W61),"") | Y61: =IF(X61<>"",IF(R61<>"",X61*R61,"Probability?"),"")
P62: =IF(COUNT(K62:O62)>0,AVERAGE(K62:O62),"") | X62: =IF(COUNT(S62:W62)>0,AVERAGE(S62:W62),"") | Y62: =IF(X62<>"",IF(R62<>"",X62*R62,"Probability?"),"")
P63: =IF(COUNT(K63:O63)>0,AVERAGE(K63:O63),"") | X63: =IF(COUNT(S63:W63)>0,AVERAGE(S63:W63),"") | Y63: =IF(X63<>"",IF(R63<>"",X63*R63,"Probability?"),"")
P64: =IF(COUNT(K64:O64)>0,AVERAGE(K64:O64),"") | X64: =IF(COUNT(S64:W64)>0,AVERAGE(S64:W64),"") | Y64: =IF(X64<>"",IF(R64<>"",X64*R64,"Probability?"),"")
P65: =IF(COUNT(K65:O65)>0,AVERAGE(K65:O65),"") | X65: =IF(COUNT(S65:W65)>0,AVERAGE(S65:W65),"") | Y65: =IF(X65<>"",IF(R65<>"",X65*R65,"Probability?"),"")
P66: =IF(COUNT(K66:O66)>0,AVERAGE(K66:O66),"") | X66: =IF(COUNT(S66:W66)>0,AVERAGE(S66:W66),"") | Y66: =IF(X66<>"",IF(R66<>"",X66*R66,"Probability?"),"")
P67: =IF(COUNT(K67:O67)>0,AVERAGE(K67:O67),"") | X67: =IF(COUNT(S67:W67)>0,AVERAGE(S67:W67),"") | Y67: =IF(X67<>"",IF(R67<>"",X67*R67,"Probability?"),"")
P68: =IF(COUNT(K68:O68)>0,AVERAGE(K68:O68),"") | X68: =IF(COUNT(S68:W68)>0,AVERAGE(S68:W68),"") | Y68: =IF(X68<>"",IF(R68<>"",X68*R68,"Probability?"),"")
P69: =IF(COUNT(K69:O69)>0,AVERAGE(K69:O69),"") | X69: =IF(COUNT(S69:W69)>0,AVERAGE(S69:W69),"") | Y69: =IF(X69<>"",IF(R69<>"",X69*R69,"Probability?"),"")
P70: =IF(COUNT(K70:O70)>0,AVERAGE(K70:O70),"") | X70: =IF(COUNT(S70:W70)>0,AVERAGE(S70:W70),"") | Y70: =IF(X70<>"",IF(R70<>"",X70*R70,"Probability?"),"")
...

Sheet Size, Schedule and Effort
A1: Project Phases | B1: Schedule | H1: Effort | K1: Schedule Metrics | M1: Effort Metrics | O1: Status | Q1: Remarks | U1: Not started | V1: In progress | W1: Waiting for inputs | X1: Deferred | Y1: Completed | Z1: {=MAX(IF(O3:O496="Completed",V3:V496,0))} -> 3
A2: Milestone Completion | B2: Estimated Start Date | C2: Estimated Completion Date | D2: Last Baselined Start Date | E2: Last Baselined Completion Date | F2: Actual Start Date | G2: Actual Completion Date | H2: Estimated Effort in Person hours | I2: Revised Effort in Person hours | J2: Actual Effort in Person hours | K2: SVA (Cumulative) | L2: SVB (Cumulative) | M2: EVA (Cumulative) | N2: EVB (Cumulative) | O2: Activity Status | P2: Customer Deliverable | R2: Est Effort Cumulative | S2: Rev. Effort Cumulative | T2: Act Effort - Cumulative | U2: Customer deliverable? | V2: Row num | X2: Applicable phases | Y2: Size Units | Z2: Project SVA goal | AA2: Project SVB Goal | AB2: Project EVA goal | AC2: Project EVB Goal | AD2: Actual Vs. Initial estimated productivity | AE2: Actual Vs. Last baselined productivity | AF2: Rev. St Date | AG2: Rev. End Date | AH2: Sch. Variance | AI2: Size unit1 | AJ2: Size unit2 | AK2: Size unit3 | AL2: Size unit4 | AM2: Size unit5 | AN2: EVA | AP2: EVB | AR2: SVA | AT2: SVB | AV2: QOW Index
A3: Analysis and Design-Rel1 | K3: =IF(AND(COUNTA(B3:C3)>1,COUNTA(F3:G3)>1,O3="Completed"),(G3-F3)/(C3-B3+1)%,"") | L3: =IF(AND(COUNTA(D3:E3)>1,COUNTA(F3:G3)>1,O3="Completed"),(G3-F3)/(E3-D3+1)%,"") | M3: =(H3-I3)/H3 -> #DIV/0! | N3: =(I3-J3)/I3 -> #DIV/0! | O3: Completed | P3: Yes | R3: =IF(H3<>"",SUMIF(H$3:H3,"<>" & "",H$3:H3),"") | S3: {=IF(O3="Completed",SUMIF(W$3:W3,"<>" & "",W$3:W3),"")} -> 0 | T3: {=IF(AND(J3<>"",O3="Completed"),SUM(IF(O$3:O3="Completed",J$3:J3,0)),"")} | U3: =IF(AND(A3<>"",P3="Yes"),ROW(),"") -> 3 | V3: =ROW() -> 3 | W3: =IF(O3="Completed",IF(COUNT($I$3:$I$596)>0,IF(I3<>"",I3,H3),""),"") | X3: =IF(ISERROR(SMALL('Control panel'!E$3:E$23,ROW()-2)),"",INDIRECT("'Control panel'!A" & SMALL('Control panel'!E$3:E$23,ROW()-2),1)) -> Analysis and design | Y3: =IF(ISERROR(SMALL('Control panel'!D$3:D$23,ROW()-2)),"",INDIRECT("'Control panel'!B" & SMALL('Control panel'!D$3:D$23,ROW()-2),2)) -> Hours | Z3: =IF(A3<>"",'Metrics planning and tracking'!$K$4,"") -> 10 | AA3: =IF(A3<>"",'Metrics planning and tracking'!$K$5,"") -> 5 | AB3: =IF(A3<>"",'Metrics planning and tracking'!$K$2,"") -> 10 | AC3: =IF(A3<>"",'Metrics planning and tracking'!$K$3,"") -> 5 | AD3: =IF(A3<>"",IF(AND(#REF!<>"",#REF!<>"",#REF!<>0),#REF!/#REF!*100,"NA"),"") -> #REF! | AE3: =IF(A3<>"",IF(AND(#REF!<>"",#REF!<>"",#REF!<>0),#REF!/#REF!*100,"NA"),"") -> #REF! | AF3: =IF($O3="Completed",IF(#REF!<>"",#REF!,IF(#REF!<>"",#REF!,"")),"") -> #REF! | AG3: =IF($O3="Completed",IF(#REF!<>"",#REF!,IF(#REF!<>"",#REF!,"")),"") -> #REF! | AH3: =IF(O3="Completed",IF(L3<>"",L3,IF(K3<>"",K3,"")),"") | AI3: Analysis | AJ3: {=IF(AND(COUNTIF('Control panel'!$A$4:$A$23,$X3)>=COLUMN(#REF!),$X3<>""),INDIRECT("'Control panel'!B" & SMALL(IF('Control panel'!$A$4:$A$23=$X3,'Control panel'!$C$4:$C$23,100),COLUMN(#REF!)),1),"")} -> #REF! | AK3: {=IF(AND(COUNTIF('Control panel'!$A$4:$A$23,$X3)>=COLUMN(#REF!),$X3<>""),INDIRECT("'Control panel'!B" & SMALL(IF('Control panel'!$A$4:$A$23=$X3,'Control panel'!$C$4:$C$23,100),COLUMN(#REF!)),1),"")} -> #REF! | AL3: {=IF(AND(COUNTIF('Control panel'!$A$4:$A$23,$X3)>=COLUMN(#REF!),$X3<>""),INDIRECT("'Control panel'!B" & SMALL(IF('Control panel'!$A$4:$A$23=$X3,'Control panel'!$C$4:$C$23,100),COLUMN(#REF!)),1),"")} -> #REF! | AM3: {=IF(AND(COUNTIF('Control panel'!$A$4:$A$23,$X3)>=COLUMN(#REF!),$X3<>""),INDIRECT("'Control panel'!B" & SMALL(IF('Control panel'!$A$4:$A$23=$X3,'Control panel'!$C$4:$C$23,100),COLUMN(#REF!)),1),"")} -> #REF! | AN3: =IF(A$3<>"",'Metrics planning and tracking'!$L$2,"") -> 15 | AO3: =IF(A$3<>"",'Metrics planning and tracking'!$M$2,"") -> 0 | AP3: =IF(A$3<>"",'Metrics planning and tracking'!$L$3,"") -> 10 | AQ3: =IF(A$3<>"",'Metrics planning and tracking'!$M$3,"") -> 0 | AR3: =IF(A$3<>"",'Metrics planning and tracking'!$L$4,"") -> 15 | AS3: =IF(A$3<>"",'Metrics planning and tracking'!$M$4,"") -> 0 | AT3: =IF(A$3<>"",'Metrics planning and tracking'!$L$5,"") -> 10 | AU3: =IF(A$3<>"",'Metrics planning and tracking'!$M$5,"") -> 0 | AV3: =IF(A3<>"",A3 & "-" &#REF! & ROW(),"") -> #REF!
